Workbook

Sheet Лист1
A2: Departure station | B2: Original city | C2: Desitional station | D2: FOB | E2: Schedule | F2: Max weight
A3: Gaoyi station via Eelian border | B3: Tianjin | C3: Купавна/ Электроугли | D3: 3950 | E3: 45767 | G3: Эрлянь
B4: Qingdao | D4: 3950 | G4: Эрлянь
B5: Shanghai/Ningbo | D5: 3800 | G5: Эрлянь
B6: Hefei Wenzhou | D6: 4000 | G6: Эрлянь
B7: Weifang | D7: 4000 | G7: Эрлянь
B8: Weihai | D8: 4050 | G8: Эрлянь
A9: Departure station | B9: Original city | C9: Desitional station | D9: FOB | E9: Schedule | F9: Max weight
A10: Datian via Erlian border | B10: Guangzhou | C10: Электроугли | D10: 4150 | E10: 45762 | G10: Эрлянь
B11: Shenshen | D11: 4150 | G11: Эрлянь
B12: Zhongshan | D12: 4150 | G12: Эрлянь
B13: Zhuhai | D13: 4150 | G13: Эрлянь
A14: Departure station | B14: Original city | C14: Desitional station | D14: FOB | E14: Schedule | F14: Max weight
A15: Jinhua station via Erlian border | B15: Ningbo | C15: Белый Раст | D15: 4350 | E15: 45761 | G15: Эрлянь
B16: Shanghai | D16: 4500 | G16: Эрлянь
B17: Jinhua | D17: 4250 | G17: Эрлянь
B18: Yiwu | D18: 4200 | G18: Эрлянь
A19: Departure station | B19: Original city | C19: Desitional station | D19: FOB | E19: Schedule | F19: Max weight
A20: Zhengzhou statiom via Alashankou border | B20: Shanghai | C20: Электроугли | D20: 4150 | E20: 18.04, 21.04, 23.04, 25.04, 30.04 | G20: Алашанкоу
B21: Ningbo | D21: 4300 | G21: Алашанкоу
B22: Qingdao | D22: 3850 | G22: Алашанкоу
B23: Tianjin | D23: 3950 | G23: Алашанкоу
B24: Yiwu | D24: 4400 | G24: Алашанкоу
B25: Zhengzhou | D25: 3450 | G25: Алашанкоу
A26: Departure station | B26: Original city | C26: Desitional station | D26: FOB | E26: Schedule | F26: Max weight
A27: Xian via Alashankou border | B27: Shanghai | C27: Электроугли | D27: 4100 | E27: 16.04, 18.04, 20.04, 22.04, 23.04 | G27: Алашанкоу
B28: Ningbo | D28: 4160 | G28: Алашанкоу
B29: Qingdao | D29: 3970 | G29: Алашанкоу
B30: Tianjin | D30: 4020 | G30: Алашанкоу
A31: Departure station | B31: Original city | C31: Desitional station | D31: FOB | E31: Schedule | F31: Max weight
A32: Suzhou via Erlian border | B32: Shanghai | C32: Электроугли | D32: 4550 | E32: 45766 | G32: Эрлянь
B33: Ningbo | D33: 4750 | G33: Эрлянь
B34: Wuxi | D34: 4600 | G34: Эрлянь
B35: Suzhou | D35: 4500 | G35: Эрлянь
A38: Электроугли | B38: 44690

Sheet Лист2
A1: Сервис | B1: Базис | C1: тип тс/ктк | D1: город или провинция отправления | E1: граница/порт | F1: город или провинция доставки | G1: стоимость USD | H1: стоимость рублей | I1: СВХ | J1: стоимость СВХ | K1: стоимость терминальной обработки | L1: автовывоз | M1: стоимость охраны | N1: валидность | O1: транзитный срок | P1: даты выходов
A2: жд | B2: =Лист1!$D$9 -> FOB | C2: 40 HC | D2: =Лист1!B3 -> Tianjin | E2: =Лист1!G3 -> Эрлянь | F2: Москва | G2: =Лист1!D3 -> 3950 | I2: =Лист1!$C$3 -> Купавна/ Электроугли | K2: =Лист1!$B$38 -> 44690 | N2: =$P$2 -> 45767 | P2: =Лист1!$E$3 -> 45767
A3: жд | B3: =Лист1!$D$9 -> FOB | C3: 40 HC | D3: =Лист1!B4 -> Qingdao | E3: =Лист1!G4 -> Эрлянь | F3: Москва | G3: =Лист1!D4 -> 3950 | I3: =Лист1!$C$3 -> Купавна/ Электроугли | K3: =Лист1!$B$38 -> 44690 | N3: =$P$2 -> 45767 | P3: =Лист1!$E$3 -> 45767
A4: жд | B4: =Лист1!$D$9 -> FOB | C4: 40 HC | D4: =Лист1!B5 -> Shanghai/Ningbo | E4: =Лист1!G5 -> Эрлянь | F4: Москва | G4: =Лист1!D5 -> 3800 | I4: =Лист1!$C$3 -> Купавна/ Электроугли | K4: =Лист1!$B$38 -> 44690 | N4: =$P$2 -> 45767 | P4: =Лист1!$E$3 -> 45767
A5: жд | B5: =Лист1!$D$9 -> FOB | C5: 40 HC | D5: =Лист1!B6 -> Hefei Wenzhou | E5: =Лист1!G6 -> Эрлянь | F5: Москва | G5: =Лист1!D6 -> 4000 | I5: =Лист1!$C$3 -> Купавна/ Электроугли | K5: =Лист1!$B$38 -> 44690 | N5: =$P$2 -> 45767 | P5: =Лист1!$E$3 -> 45767
A6: жд | B6: =Лист1!$D$9 -> FOB | C6: 40 HC | D6: =Лист1!B7 -> Weifang | E6: =Лист1!G7 -> Эрлянь | F6: Москва | G6: =Лист1!D7 -> 4000 | I6: =Лист1!$C$3 -> Купавна/ Электроугли | K6: =Лист1!$B$38 -> 44690 | N6: =$P$2 -> 45767 | P6: =Лист1!$E$3 -> 45767
A7: жд | B7: =Лист1!$D$9 -> FOB | C7: 40 HC | D7: =Лист1!B8 -> Weihai | E7: =Лист1!G8 -> Эрлянь | F7: Москва | G7: =Лист1!D8 -> 4050 | I7: =Лист1!$C$3 -> Купавна/ Электроугли | K7: =Лист1!$B$38 -> 44690 | N7: =$P$2 -> 45767 | P7: =Лист1!$E$3 -> 45767
A8: жд | B8: =Лист1!$D$9 -> FOB | C8: 40 HC | D8: =Лист1!B10 -> Guangzhou | E8: =Лист1!G10 -> Эрлянь | F8: Москва | G8: =Лист1!D10 -> 4150 | I8: =Лист1!$C$10 -> Электроугли | K8: =Лист1!$B$38 -> 44690 | N8: =$P$2 -> 45767 | P8: =Лист1!$E$10 -> 45762
A9: жд | B9: =Лист1!$D$9 -> FOB | C9: 40 HC | D9: =Лист1!B11 -> Shenshen | E9: =Лист1!G11 -> Эрлянь | F9: Москва | G9: =Лист1!D11 -> 4150 | I9: =Лист1!$C$10 -> Электроугли | K9: =Лист1!$B$38 -> 44690 | N9: =$P$2 -> 45767 | P9: =Лист1!$E$10 -> 45762
A10: жд | B10: =Лист1!$D$9 -> FOB | C10: 40 HC | D10: =Лист1!B12 -> Zhongshan | E10: =Лист1!G12 -> Эрлянь | F10: Москва | G10: =Лист1!D12 -> 4150 | I10: =Лист1!$C$10 -> Электроугли | K10: =Лист1!$B$38 -> 44690 | N10: =$P$2 -> 45767 | P10: =Лист1!$E$10 -> 45762
A11: жд | B11: =Лист1!$D$9 -> FOB | C11: 40 HC | D11: =Лист1!B13 -> Zhuhai | E11: =Лист1!G13 -> Эрлянь | F11: Москва | G11: =Лист1!D13 -> 4150 | I11: =Лист1!$C$10 -> Электроугли | K11: =Лист1!$B$38 -> 44690 | N11: =$P$2 -> 45767 | P11: =Лист1!$E$10 -> 45762
A12: жд | B12: =Лист1!$D$9 -> FOB | C12: 40 HC | D12: =Лист1!B15 -> Ningbo | E12: =Лист1!G15 -> Эрлянь | F12: Москва | G12: =Лист1!D15 -> 4350 | I12: =Лист1!$C$15 -> Белый Раст | N12: =$P$2 -> 45767 | P12: =Лист1!$E$15 -> 45761
A13: жд | B13: =Лист1!$D$9 -> FOB | C13: 40 HC | D13: =Лист1!B16 -> Shanghai | E13: =Лист1!G16 -> Эрлянь | F13: Москва | G13: =Лист1!D16 -> 4500 | I13: =Лист1!$C$15 -> Белый Раст | N13: =$P$2 -> 45767 | P13: =Лист1!$E$15 -> 45761
A14: жд | B14: =Лист1!$D$9 -> FOB | C14: 40 HC | D14: =Лист1!B17 -> Jinhua | E14: =Лист1!G17 -> Эрлянь | F14: Москва | G14: =Лист1!D17 -> 4250 | I14: =Лист1!$C$15 -> Белый Раст | N14: =$P$2 -> 45767 | P14: =Лист1!$E$15 -> 45761
A15: жд | B15: =Лист1!$D$9 -> FOB | C15: 40 HC | D15: =Лист1!B18 -> Yiwu | E15: =Лист1!G18 -> Эрлянь | F15: Москва | G15: =Лист1!D18 -> 4200 | I15: =Лист1!$C$15 -> Белый Раст | N15: =$P$2 -> 45767 | P15: =Лист1!$E$15 -> 45761
A16: жд | B16: =Лист1!$D$9 -> FOB | C16: 40 HC | D16: =Лист1!B20 -> Shanghai | E16: =Лист1!G20 -> Алашанкоу | F16: Москва | G16: =Лист1!D20 -> 4150 | I16: =Лист1!C20 -> Электроугли | N16: =$P$2 -> 45767 | P16: =Лист1!$E$20 -> 18.04, 21.04, 23.04, 25.04, 30.04
A17: жд | B17: =Лист1!$D$9 -> FOB | C17: 40 HC | D17: =Лист1!B21 -> Ningbo | E17: =Лист1!G21 -> Алашанкоу | F17: Москва | G17: =Лист1!D21 -> 4300 | I17: =Лист1!$C$10 -> Электроугли | N17: =$P$2 -> 45767 | P17: =Лист1!$E$20 -> 18.04, 21.04, 23.04, 25.04, 30.04
A18: жд | B18: =Лист1!$D$9 -> FOB | C18: 40 HC | D18: =Лист1!B22 -> Qingdao | E18: =Лист1!G22 -> Алашанкоу | F18: Москва | G18: =Лист1!D22 -> 3850 | I18: =Лист1!$C$10 -> Электроугли | N18: =$P$2 -> 45767 | P18: =Лист1!$E$20 -> 18.04, 21.04, 23.04, 25.04, 30.04
A19: жд | B19: =Лист1!$D$9 -> FOB | C19: 40 HC | D19: =Лист1!B23 -> Tianjin | E19: =Лист1!G23 -> Алашанкоу | F19: Москва | G19: =Лист1!D23 -> 3950 | I19: =Лист1!$C$10 -> Электроугли | N19: =$P$2 -> 45767 | P19: =Лист1!$E$20 -> 18.04, 21.04, 23.04, 25.04, 30.04
A20: жд | B20: =Лист1!$D$9 -> FOB | C20: 40 HC | D20: =Лист1!B24 -> Yiwu | E20: =Лист1!G24 -> Алашанкоу | F20: Москва | G20: =Лист1!D24 -> 4400 | I20: =Лист1!$C$10 -> Электроугли | N20: =$P$2 -> 45767 | P20: =Лист1!$E$20 -> 18.04, 21.04, 23.04, 25.04, 30.04
A21: жд | B21: =Лист1!$D$9 -> FOB | C21: 40 HC | D21: =Лист1!B25 -> Zhengzhou | E21: =Лист1!G25 -> Алашанкоу | F21: Москва | G21: =Лист1!D25 -> 3450 | I21: =Лист1!$C$10 -> Электроугли | N21: =$P$2 -> 45767 | P21: =Лист1!$E$20 -> 18.04, 21.04, 23.04, 25.04, 30.04
A22: жд | B22: =Лист1!$D$9 -> FOB | C22: 40 HC | D22: =Лист1!B27 -> Shanghai | E22: =Лист1!G27 -> Алашанкоу | F22: Москва | G22: =Лист1!D27 -> 4100 | I22: =Лист1!$C$27 -> Электроугли | N22: =$P$2 -> 45767 | P22: =Лист1!$E$27 -> 16.04, 18.04, 20.04, 22.04, 23.04
A23: жд | B23: =Лист1!$D$9 -> FOB | C23: 40 HC | D23: =Лист1!B28 -> Ningbo | E23: =Лист1!G28 -> Алашанкоу | F23: Москва | G23: =Лист1!D28 -> 4160 | I23: =Лист1!$C$27 -> Электроугли | N23: =$P$2 -> 45767 | P23: =Лист1!$E$27 -> 16.04, 18.04, 20.04, 22.04, 23.04
A24: жд | B24: =Лист1!$D$9 -> FOB | C24: 40 HC | D24: =Лист1!B29 -> Qingdao | E24: =Лист1!G29 -> Алашанкоу | F24: Москва | G24: =Лист1!D29 -> 3970 | I24: =Лист1!$C$27 -> Электроугли | N24: =$P$2 -> 45767 | P24: =Лист1!$E$27 -> 16.04, 18.04, 20.04, 22.04, 23.04
A25: жд | B25: =Лист1!$D$9 -> FOB | C25: 40 HC | D25: =Лист1!B30 -> Tianjin | E25: =Лист1!G30 -> Алашанкоу | F25: Москва | G25: =Лист1!D30 -> 4020 | I25: =Лист1!$C$27 -> Электроугли | N25: =$P$2 -> 45767 | P25: =Лист1!$E$27 -> 16.04, 18.04, 20.04, 22.04, 23.04
A26: жд | B26: =Лист1!$D$9 -> FOB | C26: 40 HC | D26: =Лист1!B32 -> Shanghai | E26: =Лист1!G32 -> Эрлянь | F26: Москва | G26: =Лист1!D32 -> 4550 | I26: =Лист1!$C$32 -> Электроугли | N26: =$P$2 -> 45767 | P26: =Лист1!$E$32 -> 45766
A27: жд | B27: =Лист1!$D$9 -> FOB | C27: 40 HC | D27: =Лист1!B33 -> Ningbo | E27: =Лист1!G33 -> Эрлянь | F27: Москва | G27: =Лист1!D33 -> 4750 | I27: =Лист1!$C$32 -> Электроугли | N27: =$P$2 -> 45767 | P27: =Лист1!$E$32 -> 45766
A28: жд | B28: =Лист1!$D$9 -> FOB | C28: 40 HC | D28: =Лист1!B34 -> Wuxi | E28: =Лист1!G34 -> Эрлянь | F28: Москва | G28: =Лист1!D34 -> 4600 | I28: =Лист1!$C$32 -> Электроугли | N28: =$P$2 -> 45767 | P28: =Лист1!$E$32 -> 45766
A29: жд | B29: =Лист1!$D$9 -> FOB | C29: 40 HC | D29: =Лист1!B35 -> Suzhou | E29: =Лист1!G35 -> Эрлянь | F29: Москва | G29: =Лист1!D35 -> 4500 | I29: =Лист1!$C$32 -> Электроугли | N29: =$P$2 -> 45767 | P29: =Лист1!$E$32 -> 45766
A30: =A2 -> жд | B30: FCA | C30: =C2 -> 40 HC | D30: =D2 -> Tianjin | E30: =E2 -> Эрлянь | F30: =F2 -> Москва | G30: =G2+450 -> 4400 | H30: =H2 -> 0 | I30: =I2 -> Купавна/ Электроугли | N30: =N2 -> 45767 | O30: =O2 -> 0 | P30: =P2 -> 45767
A31: =A3 -> жд | B31: FCA | C31: =C3 -> 40 HC | D31: =D3 -> Qingdao | E31: =E3 -> Эрлянь | F31: =F3 -> Москва | G31: =G3+450 -> 4400 | H31: =H3 -> 0 | I31: =I3 -> Купавна/ Электроугли | N31: =N3 -> 45767 | P31: =P3 -> 45767
A32: =A4 -> жд | B32: FCA | C32: =C4 -> 40 HC | D32: =D4 -> Shanghai/Ningbo | E32: =E4 -> Эрлянь | F32: =F4 -> Москва | G32: =G4+450 -> 4250 | H32: =H4 -> 0 | I32: =I4 -> Купавна/ Электроугли | N32: =N4 -> 45767 | P32: =P4 -> 45767
A33: =A5 -> жд | B33: FCA | C33: =C5 -> 40 HC | D33: =D5 -> Hefei Wenzhou | E33: =E5 -> Эрлянь | F33: =F5 -> Москва | G33: =G5+450 -> 4450 | H33: =H5 -> 0 | I33: =I5 -> Купавна/ Электроугли | N33: =N5 -> 45767 | P33: =P5 -> 45767
A34: =A6 -> жд | B34: FCA | C34: =C6 -> 40 HC | D34: =D6 -> Weifang | E34: =E6 -> Эрлянь | F34: =F6 -> Москва | G34: =G6+450 -> 4450 | H34: =H6 -> 0 | I34: =I6 -> Купавна/ Электроугли | N34: =N6 -> 45767 | P34: =P6 -> 45767
A35: =A7 -> жд | B35: FCA | C35: =C7 -> 40 HC | D35: =D7 -> Weihai | E35: =E7 -> Эрлянь | F35: =F7 -> Москва | G35: =G7+450 -> 4500 | H35: =H7 -> 0 | I35: =I7 -> Купавна/ Электроугли | N35: =N7 -> 45767 | P35: =P7 -> 45767
A36: =A8 -> жд | B36: FCA | C36: =C8 -> 40 HC | D36: =D8 -> Guangzhou | E36: =E8 -> Эрлянь | F36: =F8 -> Москва | G36: =G8+450 -> 4600 | H36: =H8 -> 0 | I36: =I8 -> Электроугли | N36: =N8 -> 45767 | P36: =P8 -> 45762
A37: =A9 -> жд | B37: FCA | C37: =C9 -> 40 HC | D37: =D9 -> Shenshen | E37: =E9 -> Эрлянь | F37: =F9 -> Москва | G37: =G9+450 -> 4600 | H37: =H9 -> 0 | I37: =I9 -> Электроугли | N37: =N9 -> 45767 | P37: =P9 -> 45762
A38: =A10 -> жд | B38: FCA | C38: =C10 -> 40 HC | D38: =D10 -> Zhongshan | E38: =E10 -> Эрлянь | F38: =F10 -> Москва | G38: =G10+450 -> 4600 | H38: =H10 -> 0 | I38: =I10 -> Электроугли | N38: =N10 -> 45767 | P38: =P10 -> 45762
A39: =A11 -> жд | B39: FCA | C39: =C11 -> 40 HC | D39: =D11 -> Zhuhai | E39: =E11 -> Эрлянь | F39: =F11 -> Москва | G39: =G11+450 -> 4600 | H39: =H11 -> 0 | I39: =I11 -> Электроугли | N39: =N11 -> 45767 | P39: =P11 -> 45762
A40: =A12 -> жд | B40: FCA | C40: =C12 -> 40 HC | D40: =D12 -> Ningbo | E40: =E12 -> Эрлянь | F40: =F12 -> Москва | G40: =G12+450 -> 4800 | H40: =H12 -> 0 | I40: =I12 -> Белый Раст | N40: =N12 -> 45767 | P40: =P12 -> 45761
...
