Workbook

Sheet Table 1
A1: 20 апреля 2025 г.
A2: Коммерческое предложение на перевозку грузов из Юго-Восточной Азии через порт ООО «Терминал Врангель» в Россию
A3: Указанные в настоящих предложениях ставки вступают в силу с 20 апреля 2025 года и действуют до начала действия предложения в новой редакции , применяются только в отношении Заявок Клиента на комплексную перевозку грузов полным сервисом Экспедитора, при котором только Экспедитор оказывает весь перечень услуг по доставке груза с пункта отправления до пункта назначения (в частности, как перевозку морским транспортом до границы РФ, так и последующую доставку по территории РФ). Ставки применяются для грузов, в период их действия погруженных на борт судна. 1. Морская составляющая международной перевозки FI Порт отправления - CY ООО «Терминал Врангель»:
A4: Порт погрузки | D4: Стоимость перевозки за 20'DC (COC), долл. США | H4: Стоимость перевозки за 40' HC (COC), долл. США
A5: NINGBO | D5: $1 150 | H5: $1 600
A6: SHANGHAI | D6: $1 150 | H6: $1 600
A7: RIZHAO | D7: $1 150 | H7: $1 600
A8: XINGANG* | D8: $1 650 | H8: $1 800
A9: DALIAN* | D9: $1 650 | H9: $1 800
A10: NANSHA* | D10: $1 800 | H10: $2 900
A11: *По данным портам погрузки Drop off charge возможен только в Москве. Предложение не включает линейные сборы на стороне отправления (OTHC, booking, security, handling, docs, telex release fee и иные). Предложение включает в себя DTHC в порту выгрузки. 2. Наземная составляющая международной перевозки CY Порт ООО «Терминал Врангель» - FOR Пункт назначения в РФ:
A12: Направление | B12: Стоимость транспортировки | F12: Стоимость транспортировки с учетом сменного сопровождения и охраны | J12: Drop off charge (COC)
B13: 20' < 24тонн | C13: 20' > 24 тонн | E13: 40 | F13: 20' < 24 тонн | G13: 20' > 24 тонн | I13: 40 | J13: 20 | K13: 40
A14: МОСКВА | B14: 165 000₽ | C14: 190 000₽ | E14: 235 000₽ | F14: 169 300₽ | G14: 194 300₽ | I14: 244 000₽ | J14: 0 | K14: 0
A15: ЕКАТЕРИНБУРГ | B15: 185 000₽ | C15: 208 000₽ | E15: 255 000₽ | F15: 188 400₽ | G15: 211 400₽ | I15: 294 500₽ | J15: 150 | K15: 100
A16: НОВОСИБИРСК | B16: 152 000₽ | C16: 172 000₽ | E16: 217 000₽ | F16: 171 800₽ | G16: 191 800₽ | I16: 250 200₽ | J16: 150 | K16: 100
A17: САНКТ-ПЕТЕРБУРГ | B17: 176 000₽ | C17: 202 000₽ | E17: 317 000₽ | F17: 180 700₽ | G17: 206 700₽ | I17: 326 400₽ | J17: -200 | K17: 500
A18: ТОЛЬЯТТИ | B18: 187 000₽ | C18: 211 000₽ | E18: 332 000₽ | F18: 190 800₽ | G18: 214 800₽ | I18: 339 600₽ | J18: 350 | K18: 300
A19: КРАСНОЯРСК | B19: 157 000₽ | C19: 176 000₽ | E19: 213 000₽ | F19: 175 000₽ | G19: 194 000₽ | I19: 243 100₽ | J19: 150 | K19: -250
A20: РОСТОВ-НА-ДОНУ* | B20: 199 000₽ | C20: 226 000₽ | E20: 365 000₽ | F20: 203 300₽ | G20: 230 300₽ | I20: 373 500₽ | J20: 150 | K20: 0
A21: *По направлению Ростов-На-Дону для контейнеров 40 HС тарифы действительны при условии полного мультимодального комплекса Экспедитора, включая автодоставку в конечном пункте назначения. В случае изменения по инициативе Клиента дальнейшего маршрута перевозки после прибытия груза на территорию РФ на маршрут, отличный от ранее согласованного Сторонами в Заявке, Экспедитор в праве осуществить перерасчет тарифа организации дальнейшей перевозки.
A22: 3. Условия использования предложения: - Ставки даны для грузов, перевозимых из портов, расположенных на территории иностранных государств, через ООО «Терминал Врангель» и следующих далее железнодорожным транспортом на станции сети дорог РЖД; - Ставки не применимы к перевозкам тяжеловесных, опасных и скоропортящихся грузов, грузов во флекси-танках, танк- контейнерах и иных специализированных контейнерах; - Ставки действительны для грузов, прошедших таможенное оформление в порту ООО «Терминал Врангель», которое осуществляется силами Клиента и за его счет; - Ставки на 20-ти футовые контейнеры даны при условии отправки парных контейнеров, из расчета на один 20-ти футовый контейнер;

Sheet Table 2
A1: - Масса одного грузового места не должна превышать 1500 кг веса брутто;
A2: 4. Предложение включает в себя:
A3: - Обязательные терминальные расходы при отгрузке контейнеров на жд; - Организация жд перевозки станция-станция; - Нормативный срок хранения на терминале ООО «Терминал Врангель» – 8 суток; - Экспедирование на терминале отправления;
A4: 5. Предложение не включает в себя налоги, которые начисляются и оплачиваются в соответствии с действующим законодательством, а также стоимость услуг по организации: - Загрузки/выгрузки груза в/из контейнера; - Пропуска транспортного средства к месту выгрузки; - Хранения сверх установленных портом свободных периодов; - Таможенного оформления и мероприятий по таможенному контролю; - Радиационного, иных видов контроля, взвешивания контейнеров, перемещения их по терминалу и т.д.;
A5: 6. Организация доставки груза автомобильным транспортом в рамках международной перевозки (CY cтанция назначения в РФ – FOT Пункт назначения в РФ)
A6: Направление | B6: Стоимость транспортировки
B7: 20' < 18 тонн | C7: 40' < 20 тонн
A8: МОСКВА | B8: 44 000 ₽ | C8: 47 000 ₽
A9: НОВОСИБИРСК | B9: 32 000 ₽ | C9: 33 000 ₽
A10: ЕКАТЕРИНБУРГ | B10: 37 000 ₽ | C10: 41 000 ₽
A11: САНКТ-ПЕТЕРБУРГ | B11: 40 000 ₽ | C11: 40 000 ₽
A12: РОСТОВ-НА-ДОНУ | B12: 38 000 ₽ | C12: 40 000 ₽
A13: ТОЛЬЯТТИ | B13: 38 000 ₽ | C13: 41 000 ₽
A14: КРАСНОЯРСК | B14: 28 000 ₽ | C14: 33 000 ₽
A15: ЧЕЛЯБИНСК* | B15: 64 000 ₽ | C15: 67 000 ₽
A16: УФА* | B16: 111 000 ₽ | C16: 113 000 ₽
A17: ПЕРМЬ* | B17: 81 000 ₽ | C17: 81 000 ₽
A18: ТЮМЕНЬ* | B18: 81 000 ₽ | C18: 81 000 ₽
A19: НАБЕРЕЖНЫЕ ЧЕЛНЫ* | B19: 154 000 ₽ | C19: 156 000 ₽
A20: КАЗАНЬ** | B20: 128 000 ₽ | C20: 130 000 ₽
A21: * - доставка до склада в пункте назначения со сдачей порожних контейнеров в Екатеринбурге ** - доставка до склада в пункте назначения со сдачей порожних контейнеров в Москве Ставки включают прием на станции и погрузку груженого контейнера на автомобиль и доставка его от железнодорожной станции до склада получателя. (включен один адрес доставки)
A22: В Москве доставка осуществляется в пределах МКАД, в Санкт-Петербурге в пределах КАД. Вывоз по Тольятти осуществляется для контейнеров весом брутто не более 25т. Ставки на услуги,указанные в пункте 6 применяются для перевозки 20/40 контейнеров, сумма массы-брутто груза, которого не превышает 18/20 тонн соответственно. Нормативный простой автотранспорта при выгрузке в Москве 20/40-футового контейнера 4/5 часов соответственно. Нормативный простой автотранспорта при выгрузке в Новосибирске 20/40-футового контейнера 3/4 часа соответственно. Нормативный простой автотранспорта при выгрузке в Екатеринбурге 20/40-футового контейнера 3/4 часа соответственно. Нормативный простой автотранспорта при выгрузке в Санкт-Петербурге 20/40-футового контейнера 4/5 часов соответственно. Нормативный простой автотранспорта при выгрузке в Ростове-на-Дону 20/40-футового контейнера 4/5 часов соответственно. Нормативный простой автотранспорта при выгрузке в Тольятти 20/40-футового контейнера 4 часа соответственно. Нормативный простой автотранспорта при выгрузке в Красноярске 20/40-футового контейнера 3/4 часа соответственно.

Sheet Table 3
A1: 7. Дополнительные услуги при автодоставке по Москве:
A2: Наименование услуги | C2: Стоимость
A3: Перепробег за пределы МКАД | C3: 110 ₽ / км.
A4: 8. Превышение нормы загрузки контейнеров при вывозе автотранспортом свыше 18/20 тонн:
A5: Направление | B5: Стоимость
B6: 20' > 18 тонн | D6: 40' > 20 тонн
A7: МОСКВА | B7: 2 500 ₽/ тонна | D7: 2 500 ₽/ тонна
A8: НОВОСИБИРСК | B8: 1 000 ₽/ тонна | D8: 1 000 ₽/ тонна
A9: ЕКАТЕРИНБУРГ | B9: 1 500 ₽/ тонна | D9: 1 500 ₽/ тонна
A10: САНКТ-ПЕТЕРБУРГ | B10: 1 200 ₽/ тонна | D10: 1 200 ₽/ тонна
A11: РОСТОВ-НА-ДОНУ | B11: 1 000 ₽/ тонна | D11: 1 000 ₽/ тонна
A12: ТОЛЬЯТТИ | B12: 1 000 ₽/ тонна | D12: 1 000 ₽/ тонна
A13: КРАСНОЯРСК | B13: 1 000 ₽/ тонна | D13: 1 000 ₽/ тонна
A14: 9. Простой сверх нормы автотранспорта при выгрузке:
A15: Направление | B15: Стоимость
B16: 20 | D16: 40
A17: МОСКВА | B17: 2 000 ₽/ час | D17: 2 000 ₽/ час
A18: НОВОСИБИРСК | B18: 1 100 ₽/ час | D18: 1 100 ₽/ час
A19: ЕКАТЕРИНБУРГ | B19: 1 100 ₽/ час | D19: 1 100 ₽/ час
A20: САНКТ-ПЕТЕРБУРГ | B20: 1 100 ₽/ час | D20: 1 100 ₽/ час
A21: РОСТОВ-НА-ДОНУ | B21: 1 000 ₽/ час | D21: 1 000 ₽/ час
A22: ТОЛЬЯТТИ | B22: 2 000 ₽/ час | D22: 2 000 ₽/ час
A23: КРАСНОЯРСК | B23: 1 800 ₽/ час | D23: 2 000 ₽/ час
A24: 10. Условия использования контейнеров: Нормативный период использования контейнеров, включенные в предложение (считается с момента прибытия в порт, по дату сдачи порожнего в пункте назначения):

Sheet Table 4
A1: Направление | D1: Свободный период, сутки
A2: МОСКВА, САНКТ-ПЕТЕРБУРГ, РОСТОВ-НА-ДОНУ, ТОЛЬЯТТИ | D2: 40
A3: ЕКАТЕРИНБУРГ | D3: 35
A4: НОВОСИБИРСК, КРАСНОЯРСК | D4: 30
A5: За использование контейнера сверх вышеуказанного нормативного периода, производится оплата в размере 10 долл. США за 20-футовый контейнер в сутки и 20 долл. США за 40-футовый контейнер в сутки.
A6: 11. Ставки на услуги, оказываемые на территории терминала ООО «Терминал Врангель», не включённые в предложение:
A7: Наименование услуги | C7: 20'DC | F7: 40' HC
A8: Организация хранения с 9-х по 24-е сутки, НДС 0% | C8: 2 340 ₽ | F8: 4 680 ₽
A9: Организация хранения с 25-х суток, НДС 0% | C9: 5 050 ₽ | F9: 10 100 ₽
A10: Перемещение контейнера для целей взвешивания, за контейнер, НДС 0% | C10: 7 170 ₽
A11: Перемещение контейнера для целей осмотра с использованием инспекционно-досмотрового комплекса (ИДК), НДС 0% | C11: 7 170 ₽
A12: Перемещение контейнера для целей проведения радиационного контроля, НДС 0% | C12: 4 960 ₽
A13: Приведение в транспортабельное состояние | C13: 3 300 ₽
A14: Перемещение контейнера ИСО 20’/40’ для целей осмотра/досмотра, НДС 0% | C14: 12 760 ₽ | F14: 15 810 ₽
A15: Перемещение груженого контейнера ИСО 20’/40’, НДС 0% | C15: 4 960 ₽
A16: Организация крепления грузов в контейнерах (установка заградительного щита в дверном проеме, включая перемещение груженого контейнера), НДС 0% | C16: 18 000 ₽
A17: Пломбирование контейнера (включая стоимость пломбы), НДС 0% | C17: 600 ₽
A18: Присутствие представителя при проведении таможенного досмотра до 10 артикулов, НДС 20% | C18: 18 000 ₽
A19: Присутствие представителя при проведении отбора проб и образцов, проведении процедуры СКК, КФК НДС 20% | C19: 12 000 ₽
A20: 12. Возможные дополнительные расходы по хранению на станции назначения:
A21: Станция | B21: Стоимость хранения
B22: 20 | E22: 40
A23: Электроугли (Москва) с 3-х по 6-е сутки | B23: 1 950 ₽ | E23: 3 900 ₽
A24: Электроугли (Москва) с 7-х по 10-е сутки | B24: 4 700 ₽ | E24: 9 100 ₽
A25: Электроугли (Москва) с 11-х суток | B25: 7 150 ₽ | E25: 14 300 ₽
A26: Тучково (Москва) с 5-х по 7-е сутки | B26: 5 833 ₽ | E26: 5 833 ₽
A27: Тучково (Москва) с 8-х суток | B27: 16 800 ₽ | E27: 16 800 ₽
A28: Селятино (Москва) с 3-х по 8-е сутки | B28: 1 880 ₽ | E28: 3 380 ₽
A29: Селятино (Москва) с 9-х суток | B29: 5 460 ₽ | E29: 10 660 ₽
A30: Купавна (Москва) с 4-х по 10-е сутки | B30: 1 755 ₽ | E30: 3 900 ₽
A31: Купавна (Москва) с 11-х суток | B31: 2 925 ₽ | E31: 6 250 ₽
A32: Белый Раст (Москва) с 3-х по 7-е сутки | B32: 1 500 ₽ | E32: 3 000 ₽
A33: Белый Раст (Москва) с 8-х суток по 10-е сутки | B33: 5 000 ₽ | E33: 10 000 ₽
A34: Белый Раст (Москва) с 11-х суток | B34: 6 500 ₽ | E34: 13 000 ₽
... A54: Базаиха (Красноярск) с 15-х суток | B54: 810 ₽ | E54: 1 230 ₽
A55: 13. Термины: - FOR (free on rail) – условия перевозки, при которых в тариф включена стоимость перевозки до станции назначения. Получение контейнера на станции назначения, погрузо-разгрузочные и иные работы и услуги после прибытия платформы на станцию оплачиваются Клиентом самостоятельно;
A56: - FI (free in) – условия перевозки, при которых тариф не включает расходы, производимые до погрузки груза на транспортное средство;
A57: - CY (container yard) – условия перевозки, при которых в тариф включена стоимость погрузки/выгрузки контейнера на/с транспортного средства в порту отправления/назначения; - FOT (free on truck) – условия перевозки, при которых в тариф включена стоимость перевозки автотранспортом до места назначения;

Sheet для калькулятора
A1: Сервис | B1: Базис | C1: тип тс/ктк | D1: город или провинция отправления | E1: граница/порт | F1: город или провинция доставки | G1: стоимость USD | H1: стоимость рублей | I1: СВХ | J1: стоимость СВХ | K1: стоимость терминальной обработки | L1: автовывоз | M1: стоимость охраны | N1: валидность | O1: транзитный срок | P1: даты выходов | Q1: что включено
A2: ММП | B2: FOB | C2: ='Table 1'!B13 -> 20' < 24тонн | D2: ='Table 1'!$A$5 -> NINGBO | E2: Врангель | F2: {='Table 1'!A14:A20} -> МОСКВА | G2: ='Table 1'!$D$5 -> $1 150 | H2: ='Table 1'!B14 -> 165 000₽
A3: ММП | B3: FOB | C3: =$C$2 -> 20' < 24тонн | D3: ='Table 1'!$A$5 -> NINGBO | E3: Врангель | F3: ЕКАТЕРИНБУРГ | G3: ='Table 1'!$D$5 -> $1 150 | H3: ='Table 1'!B15 -> 185 000₽
A4: ММП | B4: FOB | C4: =$C$2 -> 20' < 24тонн | D4: ='Table 1'!$A$5 -> NINGBO | E4: Врангель | F4: НОВОСИБИРСК | G4: ='Table 1'!$D$5 -> $1 150 | H4: ='Table 1'!B16 -> 152 000₽
A5: ММП | B5: FOB | C5: =$C$2 -> 20' < 24тонн | D5: ='Table 1'!$A$5 -> NINGBO | E5: Врангель | F5: САНКТ-ПЕТЕРБУРГ | G5: ='Table 1'!$D$5 -> $1 150 | H5: ='Table 1'!B17 -> 176 000₽
A6: ММП | B6: FOB | C6: =$C$2 -> 20' < 24тонн | D6: ='Table 1'!$A$5 -> NINGBO | E6: Врангель | F6: ТОЛЬЯТТИ | G6: ='Table 1'!$D$5 -> $1 150 | H6: ='Table 1'!B18 -> 187 000₽
A7: ММП | B7: FOB | C7: =$C$2 -> 20' < 24тонн | D7: ='Table 1'!$A$5 -> NINGBO | E7: Врангель | F7: КРАСНОЯРСК | G7: ='Table 1'!$D$5 -> $1 150 | H7: ='Table 1'!B19 -> 157 000₽
A8: ММП | B8: FOB | C8: =$C$2 -> 20' < 24тонн | D8: ='Table 1'!$A$5 -> NINGBO | E8: Врангель | F8: РОСТОВ-НА-ДОНУ* | G8: ='Table 1'!$D$5 -> $1 150 | H8: ='Table 1'!B20 -> 199 000₽
A9: ММП | B9: FOB | C9: =$C$2 -> 20' < 24тонн | D9: ='Table 1'!$A$6 -> SHANGHAI | E9: Врангель | F9: {='Table 1'!A14:A20} -> МОСКВА | G9: ='Table 1'!$D$6 -> $1 150 | H9: ='Table 1'!B14 -> 165 000₽
A10: ММП | B10: FOB | C10: =$C$2 -> 20' < 24тонн | D10: ='Table 1'!$A$6 -> SHANGHAI | E10: Врангель | F10: ЕКАТЕРИНБУРГ | G10: ='Table 1'!$D$6 -> $1 150 | H10: ='Table 1'!B15 -> 185 000₽
A11: ММП | B11: FOB | C11: =$C$2 -> 20' < 24тонн | D11: ='Table 1'!$A$6 -> SHANGHAI | E11: Врангель | F11: НОВОСИБИРСК | G11: ='Table 1'!$D$6 -> $1 150 | H11: ='Table 1'!B16 -> 152 000₽
A12: ММП | B12: FOB | C12: =$C$2 -> 20' < 24тонн | D12: ='Table 1'!$A$6 -> SHANGHAI | E12: Врангель | F12: САНКТ-ПЕТЕРБУРГ | G12: ='Table 1'!$D$6 -> $1 150 | H12: ='Table 1'!B17 -> 176 000₽
A13: ММП | B13: FOB | C13: =$C$2 -> 20' < 24тонн | D13: ='Table 1'!$A$6 -> SHANGHAI | E13: Врангель | F13: ТОЛЬЯТТИ | G13: ='Table 1'!$D$6 -> $1 150 | H13: ='Table 1'!B18 -> 187 000₽
A14: ММП | B14: FOB | C14: =$C$2 -> 20' < 24тонн | D14: ='Table 1'!$A$6 -> SHANGHAI | E14: Врангель | F14: КРАСНОЯРСК | G14: ='Table 1'!$D$6 -> $1 150 | H14: ='Table 1'!B19 -> 157 000₽
A15: ММП | B15: FOB | C15: =$C$2 -> 20' < 24тонн | D15: ='Table 1'!$A$6 -> SHANGHAI | E15: Врангель | F15: РОСТОВ-НА-ДОНУ* | G15: ='Table 1'!$D$6 -> $1 150 | H15: ='Table 1'!B20 -> 199 000₽
A16: ММП | B16: FOB | C16: =$C$2 -> 20' < 24тонн | D16: ='Table 1'!$A$7 -> RIZHAO | E16: Врангель | F16: {='Table 1'!A14:A20} -> МОСКВА | G16: ='Table 1'!$D$7 -> $1 150 | H16: ='Table 1'!B14 -> 165 000₽
A17: ММП | B17: FOB | C17: =$C$2 -> 20' < 24тонн | D17: ='Table 1'!$A$7 -> RIZHAO | E17: Врангель | F17: ЕКАТЕРИНБУРГ | G17: ='Table 1'!$D$7 -> $1 150 | H17: ='Table 1'!B15 -> 185 000₽
A18: ММП | B18: FOB | C18: =$C$2 -> 20' < 24тонн | D18: ='Table 1'!$A$7 -> RIZHAO | E18: Врангель | F18: НОВОСИБИРСК | G18: ='Table 1'!$D$7 -> $1 150 | H18: ='Table 1'!B16 -> 152 000₽
A19: ММП | B19: FOB | C19: =$C$2 -> 20' < 24тонн | D19: ='Table 1'!$A$7 -> RIZHAO | E19: Врангель | F19: САНКТ-ПЕТЕРБУРГ | G19: ='Table 1'!$D$7 -> $1 150 | H19: ='Table 1'!B17 -> 176 000₽
A20: ММП | B20: FOB | C20: =$C$2 -> 20' < 24тонн | D20: ='Table 1'!$A$7 -> RIZHAO | E20: Врангель | F20: ТОЛЬЯТТИ | G20: ='Table 1'!$D$7 -> $1 150 | H20: ='Table 1'!B18 -> 187 000₽
A21: ММП | B21: FOB | C21: =$C$2 -> 20' < 24тонн | D21: ='Table 1'!$A$7 -> RIZHAO | E21: Врангель | F21: КРАСНОЯРСК | G21: ='Table 1'!$D$7 -> $1 150 | H21: ='Table 1'!B19 -> 157 000₽
A22: ММП | B22: FOB | C22: =$C$2 -> 20' < 24тонн | D22: ='Table 1'!$A$7 -> RIZHAO | E22: Врангель | F22: РОСТОВ-НА-ДОНУ* | G22: ='Table 1'!$D$7 -> $1 150 | H22: ='Table 1'!B20 -> 199 000₽
A23: ММП | B23: FOB | C23: =$C$2 -> 20' < 24тонн | D23: ='Table 1'!$A$8 -> XINGANG* | E23: Врангель | F23: {='Table 1'!A14:A20} -> МОСКВА | G23: ='Table 1'!$D$8 -> $1 650 | H23: ='Table 1'!B14 -> 165 000₽
A24: ММП | B24: FOB | C24: =$C$2 -> 20' < 24тонн | D24: ='Table 1'!$A$8 -> XINGANG* | E24: Врангель | F24: ЕКАТЕРИНБУРГ | G24: ='Table 1'!$D$8 -> $1 650 | H24: ='Table 1'!B15 -> 185 000₽
A25: ММП | B25: FOB | C25: =$C$2 -> 20' < 24тонн | D25: ='Table 1'!$A$8 -> XINGANG* | E25: Врангель | F25: НОВОСИБИРСК | G25: ='Table 1'!$D$8 -> $1 650 | H25: ='Table 1'!B16 -> 152 000₽
A26: ММП | B26: FOB | C26: =$C$2 -> 20' < 24тонн | D26: ='Table 1'!$A$8 -> XINGANG* | E26: Врангель | F26: САНКТ-ПЕТЕРБУРГ | G26: ='Table 1'!$D$8 -> $1 650 | H26: ='Table 1'!B17 -> 176 000₽
A27: ММП | B27: FOB | C27: =$C$2 -> 20' < 24тонн | D27: ='Table 1'!$A$8 -> XINGANG* | E27: Врангель | F27: ТОЛЬЯТТИ | G27: ='Table 1'!$D$8 -> $1 650 | H27: ='Table 1'!B18 -> 187 000₽
A28: ММП | B28: FOB | C28: =$C$2 -> 20' < 24тонн | D28: ='Table 1'!$A$8 -> XINGANG* | E28: Врангель | F28: КРАСНОЯРСК | G28: ='Table 1'!$D$8 -> $1 650 | H28: ='Table 1'!B19 -> 157 000₽
A29: ММП | B29: FOB | C29: =$C$2 -> 20' < 24тонн | D29: ='Table 1'!$A$9 -> DALIAN* | E29: Врангель | F29: РОСТОВ-НА-ДОНУ* | G29: ='Table 1'!$D$8 -> $1 650 | H29: ='Table 1'!B20 -> 199 000₽
A30: ММП | B30: FOB | C30: =$C$2 -> 20' < 24тонн | D30: ='Table 1'!$A$9 -> DALIAN* | E30: Врангель | F30: {='Table 1'!A14:A20} -> МОСКВА | G30: ='Table 1'!$D$9 -> $1 650 | H30: ='Table 1'!B14 -> 165 000₽
A31: ММП | B31: FOB | C31: =$C$2 -> 20' < 24тонн | D31: ='Table 1'!$A$9 -> DALIAN* | E31: Врангель | F31: ЕКАТЕРИНБУРГ | G31: ='Table 1'!$D$9 -> $1 650 | H31: ='Table 1'!B15 -> 185 000₽
A32: ММП | B32: FOB | C32: =$C$2 -> 20' < 24тонн | D32: ='Table 1'!$A$9 -> DALIAN* | E32: Врангель | F32: НОВОСИБИРСК | G32: ='Table 1'!$D$9 -> $1 650 | H32: ='Table 1'!B16 -> 152 000₽
A33: ММП | B33: FOB | C33: =$C$2 -> 20' < 24тонн | D33: ='Table 1'!$A$9 -> DALIAN* | E33: Врангель | F33: САНКТ-ПЕТЕРБУРГ | G33: ='Table 1'!$D$9 -> $1 650 | H33: ='Table 1'!B17 -> 176 000₽
A34: ММП | B34: FOB | C34: =$C$2 -> 20' < 24тонн | D34: ='Table 1'!$A$9 -> DALIAN* | E34: Врангель | F34: ТОЛЬЯТТИ | G34: ='Table 1'!$D$9 -> $1 650 | H34: ='Table 1'!B18 -> 187 000₽
A35: ММП | B35: FOB | C35: =$C$2 -> 20' < 24тонн | D35: ='Table 1'!$A$9 -> DALIAN* | E35: Врангель | F35: КРАСНОЯРСК | G35: ='Table 1'!$D$9 -> $1 650 | H35: ='Table 1'!B19 -> 157 000₽
A36: ММП | B36: FOB | C36: =$C$2 -> 20' < 24тонн | D36: ='Table 1'!$A$9 -> DALIAN* | E36: Врангель | F36: РОСТОВ-НА-ДОНУ* | G36: ='Table 1'!$D$9 -> $1 650 | H36: ='Table 1'!B20 -> 199 000₽
A37: ММП | B37: FOB | C37: =$C$2 -> 20' < 24тонн | D37: ='Table 1'!$A$10 -> NANSHA* | E37: Врангель | F37: {='Table 1'!A14:A20} -> МОСКВА | G37: ='Table 1'!$D$10 -> $1 800 | H37: ='Table 1'!B14 -> 165 000₽
A38: ММП | B38: FOB | C38: =$C$2 -> 20' < 24тонн | D38: ='Table 1'!$A$10 -> NANSHA* | E38: Врангель | F38: ЕКАТЕРИНБУРГ | G38: ='Table 1'!$D$10 -> $1 800 | H38: ='Table 1'!B15 -> 185 000₽
A39: ММП | B39: FOB | C39: =$C$2 -> 20' < 24тонн | D39: ='Table 1'!$A$10 -> NANSHA* | E39: Врангель | F39: НОВОСИБИРСК | G39: ='Table 1'!$D$10 -> $1 800 | H39: ='Table 1'!B16 -> 152 000₽
A40: ММП | B40: FOB | C40: =$C$2 -> 20' < 24тонн | D40: ='Table 1'!$A$10 -> NANSHA* | E40: Врангель | F40: САНКТ-ПЕТЕРБУРГ | G40: ='Table 1'!$D$10 -> $1 800 | H40: ='Table 1'!B17 -> 176 000₽
...
