Workbook

Sheet Sea (FOB)
A1: Sea - China to VVO/VYP
A2: POL | B2: POD | C2: Carrier | D2: 20GP SOC | E2: 40HQ SOC | F2: 20GP COC | G2: 40HQ COC | H2: ETD | I2: Later shipping date (price needs to be recalculated)
A3: HONG KONG | B3: VLADIVISTOK COMMERCIAL/FISHERY | C3: SINOKOR | D3: 1550 | E3: 2500 | F3: 2850 | G3: 4500 | H3: 45763
A4: NANSHA | B4: Vrangel Bay (VOSTOCHNY) | C4: STF(CSTAR) | D4: 1075 | E4: 1200 | F4: 1825 | G4: 2550 | H4: 45770 | I4: 4.29
A5: NANSHA | B5: VLADIVISTOK COMMERCIAL/FISHERY | C5: SINOKOR | D5: 950 | E5: 1400 | F5: 1700 | G5: 2750 | H5: 45763 | I5: VIA HONG KONG
A6: NANSHA | B6: VLADIVISTOK COMMERCIAL | C6: FESCO | D6: 975 | E6: 1175 | F6: 1725 | G6: 2525 | H6: 45765
A7: SEHKOU | B7: VLADIVISTOK COMMERCIAL/FISHERY | C7: SINOKOR | D7: 850 | E7: 1150 | F7: 1600 | G7: 2550 | H7: 45764
A8: YANTIAN | B8: Vrangel Bay (VOSTOCHNY) | C8: STF(CSTAR) | D8: 1075 | E8: 1200 | F8: 1825 | G8: 2600 | H8: 45769 | I8: 4.28
A9: YANTIAN | B9: VLADIVISTOK COMMERCIAL | C9: FESCO | D9: 975 | E9: 1175 | F9: 1725 | G9: 2575 | H9: 45761
A10: XIAMEN | B10: Vrangel Bay (VOSTOCHNY) | C10: STF(CSTAR) | D10: 1075 | E10: 1200 | F10: 1825 | G10: 2800 | H10: 45772
A11: XIAMEN | B11: VLADIVISTOK COMMERCIAL/FISHERY | C11: HEUNG-A/SINOKOR | D11: 850 | E11: 1100 | F11: 1600 | G11: 2700 | H11: 45759 | I11: 4.18
A12: XIAMEN | B12: VLADIVISTOK COMMERCIAL | C12: FESCO | D12: 950 | E12: 1100 | F12: 1700 | G12: 2700 | H12: 45763
A13: SHANGHAI | B13: VLADIVISTOK COMMERCIAL/FISHERY | C13: HEUNG-A | D13: 680 | E13: 960 | F13: 1430 | G13: 2110 | H13: 45765
A14: SHANGHAI | B14: VLADIVISTOK COMMERCIAL/FISHERY | C14: SINOKOR | D14: 680 | E14: 960 | F14: 1430 | G14: 2110 | H14: 45765
A15: SHANGHAI | B15: VLADIVISTOK COMMERCIAL | C15: FESCO | D15: 850 | E15: 1000 | F15: 1600 | G15: 2150 | H15: 45761 | I15: 4.21
A16: SHANGHAI | B16: Vrangel Bay (VOSTOCHNY) | C16: STF(CSTAR) | D16: 940 | E16: 1115 | F16: 1690 | G16: 2265 | H16: 45762 | I16: 4.28
A17: SHANGHAI | B17: VLADIVISTOK COMMERCIAL/FISHERY | C17: SCO | D17: 750 | E17: 1000 | F17: 1500 | G17: 2150 | H17: 45760 | I17: 4.20
A18: SHANGHAI | B18: Vrangel Bay (VOSTOCHNY) | C18: PING AN | D18: 750 | E18: 900 | F18: 1500 | G18: 2050 | H18: 45762
A19: TAICANG | B19: Vrangel Bay (VOSTOCHNY) | C19: SWIFT LINE | D19: 650 | E19: 900 | F19: 1400 | G19: 2050 | H19: 45762
A20: NINGBO | B20: Vrangel Bay (VOSTOCHNY) | C20: STF(CSTAR) | D20: 925 | E20: 1100 | F20: 1675 | G20: 2400 | H20: 45770
A21: NINGBO | B21: VLADIVISTOK COMMERCIAL | C21: FESCO | D21: 900 | E21: 1150 | F21: 1650 | G21: 2450 | H21: 45765
A22: NINGBO | B22: VLADIVISTOK COMMERCIAL/FISHERY | C22: HEUNG-A | D22: 700 | E22: 950 | F22: 1450 | G22: 2250 | H22: 45763
A23: NINGBO | B23: VLADIVISTOK COMMERCIAL/FISHERY | C23: SINOKOR | D23: 700 | E23: 950 | F23: 1450 | G23: 2250 | H23: 45763
A24: NINGBO | B24: VLADIVISTOK COMMERCIAL | C24: GANG TONG | D24: 800 | E24: 975 | F24: 1550 | G24: 2275 | H24: 45766
A25: NINGBO | B25: Vrangel Bay (VOSTOCHNY) | C25: HUA XIN | D25: 700 | E25: 900 | F25: 1450 | G25: 2200 | H25: 45764
A26: NINGBO | B26: VLADIVISTOK FISH PORT | C26: HUA XIN | D26: 700 | E26: 900 | F26: 1450 | G26: 2200 | H26: 45764
A27: NINGBO | B27: Vrangel Bay (VOSTOCHNY) | C27: SWIFT LINE | D27: 650 | E27: 900 | F27: 1400 | G27: 2200 | H27: 45764
A28: RIZHAO | B28: Vrangel Bay (VOSTOCHNY) | C28: STF(CSTAR) | D28: 925 | E28: 1100 | F28: 1675 | G28: 2100 | H28: 45770
A29: RIZHAO | B29: Vrangel Bay (VOSTOCHNY) | C29: PING AN | D29: 750 | E29: 900 | F29: 1500 | G29: 1900 | H29: 45764
... A32: QINGDAO | B32: Vrangel Bay (VOSTOCHNY) | C32: YOU LIAN | D32: 600 | E32: 750 | F32: 1350 | G32: 1750 | H32: 45761
A33: QINGDAO | B33: Vrangel Bay (VOSTOCHNY) | C33: SWIFT LINE | D33: 750 | E33: 1050 | F33: 1500 | G33: 2050 | H33: 45766 | I33: via RIZHAO
A34: QINGDAO | B34: VLADIVISTOK COMMERCIAL | C34: GANG TONG | D34: 800 | E34: 975 | F34: 1550 | G34: 1975 | H34: 45763
A35: QINGDAO | B35: Vrangel Bay (VOSTOCHNY) | C35: GANG TONG | D35: 800 | E35: 975 | F35: 1550 | G35: 1975 | H35: 45775
A36: QINGDAO | B36: Vrangel Bay (VOSTOCHNY) | C36: HUA XIN | D36: 700 | E36: 900 | F36: 1450 | G36: 1900 | H36: 45396
A37: QINGDAO | B37: VLADIVISTOK FISH PORT/SOLLER | C37: HUA XIN | D37: 700 | E37: 900 | F37: 1450 | G37: 1900 | H37: 45396
A38: QINGDAO | B38: VLADIVISTOK COMMERCIAL | C38: CAREN | D38: 830 | E38: 1080 | F38: 1580 | G38: 2080 | H38: 45760
A39: QINGDAO | B39: VLADIVISTOK COMMERCIAL/FISHERY | C39: SCO | D39: 750 | E39: 1000 | F39: 1500 | G39: 2000 | H39: 45762 | I39: 4.22
A40: TIANJIN | B40: Vrangel Bay (VOSTOCHNY) | C40: SWIFT LINE | D40: 650 | E40: 900 | F40: 1400 | G40: 1950 | H40: 45769
A41: TIANJIN | B41: VLADIVISTOK COMMERCIAL/FISHERY | C41: SINOKOR | D41: 850 | E41: 1100 | F41: 1600 | G41: 2150 | H41: 45764 | I41: 4.20
A42: TIANJIN | B42: Vrangel Bay (VOSTOCHNY) | C42: PING AN | D42: 750 | E42: 900 | F42: 1500 | G42: 1950 | H42: 45768
...

Sheet Rail (EXW)
A1: Departure city | B1: Route | C1: Destination | D1: EXW Term Rate(USD/40HQ) | E1: ETD | F1: Remark
A2: Shanghai/Suzhou | B2: Zhengzhou station - Elian border - Moscow Elektrougli | C2: Moscow | D2: 4850 | E2: 4.16/4.25/4.30 | G2: Erlian | H2: Elektrougli
A3: Ningbo/Cixi | C3: Moscow | D3: 5050 | E3: =$E$2 -> 4.16/4.25/4.30 | G3: Erlian | H3: Elektrougli
A4: Qingdao/Linyi | C4: Moscow | D4: 4750 | E4: =$E$2 -> 4.16/4.25/4.30 | G4: Erlian | H4: Elektrougli
A5: Tianjin/Cangzhou | C5: Moscow | D5: 5450 | E5: =$E$2 -> 4.16/4.25/4.30 | G5: Erlian | H5: Elektrougli
A6: Luoyang/Jiaozuo | C6: Moscow | D6: 4400 | E6: =$E$2 -> 4.16/4.25/4.30 | G6: Erlian | H6: Elektrougli
A7: Xiamen | C7: Moscow | D7: 5700 | E7: =$E$2 -> 4.16/4.25/4.30 | G7: Erlian | H7: Elektrougli
A8: Guangzhou | C8: Moscow | D8: 5550 | E8: =$E$2 -> 4.16/4.25/4.30 | G8: Erlian | H8: Elektrougli
A9: Shenzhen | C9: Moscow | D9: 5500 | E9: =$E$2 -> 4.16/4.25/4.30 | G9: Erlian | H9: Elektrougli
A10: Zhongshan | C10: Moscow | D10: 5600 | E10: =$E$2 -> 4.16/4.25/4.30 | G10: Erlian | H10: Elektrougli
A12: Shijiazhuang/Hengshui/Tianjin | B12: Shijiazhuang station - Elian border - Moscow Elektrougli | C12: Moscow | D12: 4650 | E12: 4.25/4.29 | G12: Erlian | H12: Elektrougli
A13: Beijing | C13: Moscow | D13: 4800 | E13: 4.25/4.29 | G13: Erlian | H13: Elektrougli
A14: Jianan/Qingdao | C14: Moscow | D14: 4850 | E14: 4.25/4.29 | G14: Erlian | H14: Elektrougli
A15: Tengzhou | C15: Moscow | D15: 5000 | E15: 4.25/4.29 | G15: Erlian | H15: Elektrougli
A17: Shanghai/Suzhou/Changzhou/Zhenjiang/Nantong | B17: Xuzhou station - Khorgos border - Manzhouli border - Moscow | C17: Moscow | D17: 5280 | E17: 45773 | G17: Khorgos | H17: Elektrougli
A18: Tianjin | C18: Moscow | D18: 5230 | E18: 45773 | G18: Khorgos | H18: Elektrougli
A19: Qingdao | C19: Moscow | D19: 5150 | E19: 45773 | G19: Khorgos | H19: Elektrougli
A21: Tianjin/Binhai | B21: Tianjin station - Elian border - Moscow Bely rast | C21: Moscow | D21: 4250 | E21: 4.17/4.24 | G21: Erlian | H21: Bely rast
A22: Qingdao/Shouguang/Zibo/Weifang | C22: Moscow | D22: 4550 | E22: 4.17/4.24 | G22: Erlian | H22: Bely rast
A23: Langfang/Cangzhou | C23: Moscow | D23: 4350 | E23: 4.17/4.24 | G23: Erlian | H23: Bely rast
A24: Tangshan | C24: Moscow | D24: 4350 | E24: 4.17/4.24 | G24: Erlian | H24: Bely rast
A25: Beijing/Shunyi/Tongzhou | C25: Moscow | D25: 4450 | E25: 4.17/4.24 | G25: Erlian | H25: Bely rast
A26: Shanghai/Suzhou | C26: Moscow | D26: 4900 | E26: 4.17/4.24 | G26: Erlian | H26: Bely rast
A27: Ningbo | C27: Moscow | D27: 5050 | E27: 4.17/4.24 | G27: Erlian | H27: Bely rast
A28: Xingtai | C28: Moscow | D28: 4400 | E28: 4.17/4.24 | G28: Erlian | H28: Bely rast
A29: Jinan/Shouguang | C29: Moscow | D29: 4550 | E29: 4.17/4.24 | G29: Erlian | H29: Bely rast
A31: Chongqing | B31: Chongqing station - Alashankou/Khorgos border - Moscow Elektrougli/Selyatino | C31: Moscow | D31: 3600 | E31: 4.16/4.19/4.23/4.26 | F31: Complete loading 11 days before ETD | G31: {=K111:K112} -> #VALUE! | H31: =M111 -> Elektrougli/Selyatino
A32: Chengdu | C32: Moscow | D32: 3750 | E32: =$E$31 -> 4.16/4.19/4.23/4.26 | G32: {=K112:K113} -> #VALUE! | H32: =M112 -> Shushary
A33: Guangzhou | C33: Moscow | D33: 4600 | E33: =$E$31 -> 4.16/4.19/4.23/4.26 | G33: {=K113:K114} -> #VALUE! | H33: =M113 -> Selyatino
A34: Shenzhen/Jiangmen/Qingyuan | C34: Moscow | D34: 4700 | E34: =$E$31 -> 4.16/4.19/4.23/4.26 | G34: {=K114:K115} -> #VALUE! | H34: =M114 -> Kolyadichi
A35: Foshan/Shunde/Zhongshan | C35: Moscow | D35: 4650 | E35: =$E$31 -> 4.16/4.19/4.23/4.26 | G35: {=K115:K116} -> #VALUE! | H35: =M115 -> Yekaterinburg
A36: Huizhou/Zhaoqing/Zhuhai/Yunfu | C36: Moscow | D36: 4750 | E36: =$E$31 -> 4.16/4.19/4.23/4.26 | G36: {=K116:K117} -> #VALUE! | H36: =M116 -> Novosibirsk
A37: Shantou/Chaozhou | C37: Moscow | D37: 5050 | E37: =$E$31 -> 4.16/4.19/4.23/4.26 | G37: {=L61:L62} -> 0 | H37: =M117 -> Moscow
G38: 0
A39: Chengdu | B39: Chengdu station - Manzhouli border - Moscow Elektrougli Chengdu station - Elian border - Moscow Elektrougli | C39: Moscow | D39: 3550 | E39: 4.18/4.21/4.25/4.29 | F39: Complete loading 10 days before ETD | G39: Erlian | H39: Elektrougli
A40: Chongqing | C40: Moscow | D40: 4050 | E40: =$E$39 -> 4.18/4.21/4.25/4.29 | G40: Erlian | H40: Elektrougli
A41: Tianjin | C41: Moscow | D41: 5750 | E41: =$E$39 -> 4.18/4.21/4.25/4.29 | G41: Erlian | H41: Elektrougli
A42: Qingdao | C42: Moscow | D42: 5000 | E42: =$E$39 -> 4.18/4.21/4.25/4.29 | G42: Erlian | H42: Elektrougli
A43: Shanghai | C43: Moscow | D43: 5050 | E43: =$E$39 -> 4.18/4.21/4.25/4.29 | G43: Erlian | H43: Elektrougli
A44: Ningbo | C44: Moscow | D44: 5200 | E44: =$E$39 -> 4.18/4.21/4.25/4.29 | G44: Erlian | H44: Elektrougli
...

Sheet Truck
A1: RATES FOR TRUCKING SERVICE FROM CHINA TO Russia/Belarus
A2: Type of goods:Carton cargo, general cargo, palletised cargo, equipment cargo
A3: Available truck Type：Box truck（82CBM,22TONS）/Tilt truck（82CBM,22TONS）
B4: Unloading City | E4: CN BORDER:Alashankou(USD) Truck Type： Box truck（82CBM,22TONS） Tilt truck（82CBM,22TONS） | F4: TRANSIT TIME (DAYS) | G4: VIA PORT
A5: 深圳/广州 Shenzhen/Guangzhou | B5: RUS | C5: Moscow（Москва） | D5: 莫斯科 | E5: 10100 | F5: 18-20 | G5: Erenhot | H5: Shenzhen/Guangzhou
B6: RUS | C6: St. Petersburg（Санкт-Петербург） | D6: 圣彼得堡 | E6: 10400 | F6: 18-22 | H6: Shenzhen/Guangzhou
B7: RUS | C7: Novosibirsk（Новосибирск） | D7: 新西伯利亚 | E7: 8500 | F7: 18-20 | H7: Shenzhen/Guangzhou
B8: BY | C8: Minsk（Минск） | D8: 明斯克 | E8: 10800 | F8: 18-22 | H8: Shenzhen/Guangzhou
B9: RUS | C9: Chelyabinsk（Челябинск） | D9: 车里雅宾斯克 | E9: 9000 | F9: 18-20 | H9: Shenzhen/Guangzhou
B10: RUS | C10: Nizhny Novgorod(Нижний Новгород) | D10: 下诺夫哥罗德 | E10: 9800 | F10: 18-20 | H10: Shenzhen/Guangzhou
B11: RUS | C11: Krasnoyar（Краснояр） | D11: 克拉斯诺亚尔 | E11: 8300 | F11: 15-18 | H11: Shenzhen/Guangzhou
B12: RUS | C12: Irkutsk（Иркутск） | D12: 伊尔库茨克 | E12: 7800 | F12: 15-18 | H12: Shenzhen/Guangzhou
B13: RUS | C13: Novokuznetsk（Новокузнецк） | D13: 新库茨涅茨克 | E13: 8500 | F13: 15-18 | H13: Shenzhen/Guangzhou
A14: 厦门 Xiamen | B14: RUS | C14: Moscow（Москва） | D14: 莫斯科 | E14: 10100 | F14: 18-20 | G14: Erenhot | H14: Xiamen
B15: RUS | C15: St. Petersburg（Санкт-Петербург） | D15: 圣彼得堡 | E15: 10400 | F15: 18-20 | H15: Xiamen
B16: RUS | C16: Novosibirsk（Новосибирск） | D16: 新西伯利亚 | E16: 8500 | F16: 18-20 | H16: Xiamen
B17: BY | C17: Minsk（Минск） | D17: 明斯克 | E17: 10800 | F17: 18-22 | H17: Xiamen
B18: RUS | C18: Chelyabinsk（Челябинск） | D18: 车里雅宾斯克 | E18: 9000 | F18: 18-20 | H18: Xiamen
B19: RUS | C19: Nizhny Novgorod(Нижний Новгород) | D19: 下诺夫哥罗德 | E19: 9800 | F19: 18-20 | H19: Xiamen
B20: RUS | C20: Krasnoyar（Краснояр） | D20: 克拉斯诺亚尔 | E20: 8300 | F20: 15-18 | H20: Xiamen
B21: RUS | C21: Irkutsk（Иркутск） | D21: 伊尔库茨克 | E21: 7800 | F21: 15-18 | H21: Xiamen
B22: RUS | C22: Novokuznetsk（Новокузнецк） | D22: 新库茨涅茨克 | E22: 8500 | F22: 15-18 | H22: Xiamen
A23: 宁波 Ningbo | B23: RUS | C23: Moscow（Москва） | D23: 莫斯科 | E23: 9500 | F23: 18-20 | G23: Erenhot | H23: Ningbo
B24: RUS | C24: St. Petersburg（Санкт-Петербург） | D24: 圣彼得堡 | E24: 9800 | F24: 18-22 | H24: Ningbo
B25: RUS | C25: Novosibirsk（Новосибирск） | D25: 新西伯利亚 | E25: 7900 | F25: 18-20 | H25: Ningbo
B26: BY | C26: Minsk（Минск） | D26: 明斯克 | E26: 10200 | F26: 18-22 | H26: Ningbo
B27: RUS | C27: Chelyabinsk（Челябинск） | D27: 车里雅宾斯克 | E27: 8400 | F27: 18-20 | H27: Ningbo
B28: RUS | C28: Nizhny Novgorod(Нижний Новгород) | D28: 下诺夫哥罗德 | E28: 9200 | F28: 18-20 | H28: Ningbo
B29: RUS | C29: Krasnoyar（Краснояр） | D29: 克拉斯诺亚尔 | E29: 7700 | F29: 15-18 | H29: Ningbo
B30: RUS | C30: Irkutsk（Иркутск） | D30: 伊尔库茨克 | E30: 7200 | F30: 15-18 | H30: Ningbo
B31: RUS | C31: Novokuznetsk（Новокузнецк） | D31: 新库茨涅茨克 | E31: 7900 | F31: 15-18 | H31: Ningbo
A32: 上海 Shanghai | B32: RUS | C32: Moscow（Москва） | D32: 莫斯科 | E32: 9400 | F32: 18-20 | G32: Erenhot | H32: Shanghai
B33: RUS | C33: St. Petersburg（Санкт-Петербург） | D33: 圣彼得堡 | E33: 9700 | F33: 18-20 | H33: Shanghai
B34: RUS | C34: Novosibirsk（Новосибирск） | D34: 新西伯利亚 | E34: 7800 | F34: 18-20 | H34: Shanghai
B35: BY | C35: Minsk（Минск） | D35: 明斯克 | E35: 10100 | F35: 18-22 | H35: Shanghai
B36: RUS | C36: Chelyabinsk（Челябинск） | D36: 车里雅宾斯克 | E36: 8300 | F36: 18-20 | H36: Shanghai
B37: RUS | C37: Nizhny Novgorod(Нижний Новгород) | D37: 下诺夫哥罗德 | E37: 9100 | F37: 18-20 | H37: Shanghai
B38: RUS | C38: Krasnoyar（Краснояр） | D38: 克拉斯诺亚尔 | E38: 7600 | F38: 15-18 | H38: Shanghai
B39: RUS | C39: Irkutsk（Иркутск） | D39: 伊尔库茨克 | E39: 7100 | F39: 15-18 | H39: Shanghai
B40: RUS | C40: Novokuznetsk（Новокузнецк） | D40: 新库茨涅茨克 | E40: 7800 | F40: 15-18 | H40: Shanghai
...

Sheet Southeast Asia - Russia
A1: POL | G1: To Moscow USD/40HQ | H1: To St. Petersburg USD/40HQ | I1: To Minsk USD/40HQ | J1: TT/DAY
A2: FOB Hanoi Station | G2: 6900 | H2: 8100 | I2: 8400 | J2: 36
A3: FOB Hochiminh Station | G3: 7450 | H3: 8650 | I3: 8950 | J3: 36
A4: FOB Hai Phong | G4: 6850 | H4: 8050 | I4: 8350 | J4: 40
A5: FOB Hochiminh City | G5: 6900 | H5: 8100 | I5: 8400 | J5: 40
A6: FOB Singapore | G6: 7100 | H6: 8300 | I6: 8600 | J6: 42
A7: FOB Laem Chabang/Bangkok | G7: 7000 | H7: 8200 | I7: 8500 | J7: 40
A8: FOB Keelung/Kaohsiung/Taichung | G8: 6900 | H8: 8100 | I8: 8400 | J8: 38
A9: FOB Pasir Gudang/Penang/Klang | G9: 7000 | H9: 8200 | I9: 8500 | J9: 40
A10: FOB Tokyo/Osaka | G10: 7000 | H10: 8200 | I10: 8500 | J10: 36
A11: FOB Colombo | G11: 7200 | H11: 8400 | I11: 8700 | J11: 45
A12: FOB Hong Kong | G12: 7300 | H12: 8500 | I12: 8800 | J12: 34
A13: FOB Sihanoukville | G13: 7300 | H13: 8500 | I13: 8800 | J13: 40
... A18: FOB Chittagong/Dhaka | G18: 7100 | H18: 8300 | I18: 8600 | J18: 42
A20: Note: The quotation is valid until the end of April 2025

Sheet для калькулятора
A1: Сервис | B1: Базис | C1: тип тс/ктк | D1: город или провинция отправления | E1: граница/порт | F1: город или провинция доставки | G1: стои-мость USD | H1: стоимость рублей | I1: СВХ | J1: стоимость СВХ | K1: стоимость терминальной обработки | L1: автовывоз | M1: стоимость охраны | N1: валидность | O1: транзитный срок | P1: даты выходов | Q1: что включено
A2: море | B2: FOB | C2: ='Sea (FOB)'!$F$2 -> 20GP COC | D2: ='Sea (FOB)'!A3 -> HONG KONG | E2: ='Sea (FOB)'!B3 -> VLADIVISTOK COMMERCIAL/FISHERY | G2: ='Sea (FOB)'!F3 -> 2850 | P2: ='Sea (FOB)'!H3 -> 45763
A3: море | B3: FOB | C3: ='Sea (FOB)'!$F$2 -> 20GP COC | D3: ='Sea (FOB)'!A4 -> NANSHA | E3: ='Sea (FOB)'!B4 -> Vrangel Bay (VOSTOCHNY) | G3: ='Sea (FOB)'!F4 -> 1825 | P3: ='Sea (FOB)'!H4 -> 45770
A4: море | B4: FOB | C4: ='Sea (FOB)'!$F$2 -> 20GP COC | D4: ='Sea (FOB)'!A5 -> NANSHA | E4: ='Sea (FOB)'!B5 -> VLADIVISTOK COMMERCIAL/FISHERY | G4: ='Sea (FOB)'!F5 -> 1700 | P4: ='Sea (FOB)'!H5 -> 45763
A5: море | B5: FOB | C5: ='Sea (FOB)'!$F$2 -> 20GP COC | D5: ='Sea (FOB)'!A6 -> NANSHA | E5: ='Sea (FOB)'!B6 -> VLADIVISTOK COMMERCIAL | G5: ='Sea (FOB)'!F6 -> 1725 | P5: ='Sea (FOB)'!H6 -> 45765
A6: море | B6: FOB | C6: ='Sea (FOB)'!$F$2 -> 20GP COC | D6: ='Sea (FOB)'!A7 -> SEHKOU | E6: ='Sea (FOB)'!B7 -> VLADIVISTOK COMMERCIAL/FISHERY | G6: ='Sea (FOB)'!F7 -> 1600 | P6: ='Sea (FOB)'!H7 -> 45764
A7: море | B7: FOB | C7: ='Sea (FOB)'!$F$2 -> 20GP COC | D7: ='Sea (FOB)'!A8 -> YANTIAN | E7: ='Sea (FOB)'!B8 -> Vrangel Bay (VOSTOCHNY) | G7: ='Sea (FOB)'!F8 -> 1825 | P7: ='Sea (FOB)'!H8 -> 45769
A8: море | B8: FOB | C8: ='Sea (FOB)'!$F$2 -> 20GP COC | D8: ='Sea (FOB)'!A9 -> YANTIAN | E8: ='Sea (FOB)'!B9 -> VLADIVISTOK COMMERCIAL | G8: ='Sea (FOB)'!F9 -> 1725 | P8: ='Sea (FOB)'!H9 -> 45761
A9: море | B9: FOB | C9: ='Sea (FOB)'!$F$2 -> 20GP COC | D9: ='Sea (FOB)'!A10 -> XIAMEN | E9: ='Sea (FOB)'!B10 -> Vrangel Bay (VOSTOCHNY) | G9: ='Sea (FOB)'!F10 -> 1825 | P9: ='Sea (FOB)'!H10 -> 45772
A10: море | B10: FOB | C10: ='Sea (FOB)'!$F$2 -> 20GP COC | D10: ='Sea (FOB)'!A11 -> XIAMEN | E10: ='Sea (FOB)'!B11 -> VLADIVISTOK COMMERCIAL/FISHERY | G10: ='Sea (FOB)'!F11 -> 1600 | P10: ='Sea (FOB)'!H11 -> 45759
A11: море | B11: FOB | C11: ='Sea (FOB)'!$F$2 -> 20GP COC | D11: ='Sea (FOB)'!A12 -> XIAMEN | E11: ='Sea (FOB)'!B12 -> VLADIVISTOK COMMERCIAL | G11: ='Sea (FOB)'!F12 -> 1700 | P11: ='Sea (FOB)'!H12 -> 45763
A12: море | B12: FOB | C12: ='Sea (FOB)'!$F$2 -> 20GP COC | D12: ='Sea (FOB)'!A13 -> SHANGHAI | E12: ='Sea (FOB)'!B13 -> VLADIVISTOK COMMERCIAL/FISHERY | G12: ='Sea (FOB)'!F13 -> 1430 | P12: ='Sea (FOB)'!H13 -> 45765
A13: море | B13: FOB | C13: ='Sea (FOB)'!$F$2 -> 20GP COC | D13: ='Sea (FOB)'!A14 -> SHANGHAI | E13: ='Sea (FOB)'!B14 -> VLADIVISTOK COMMERCIAL/FISHERY | G13: ='Sea (FOB)'!F14 -> 1430 | P13: ='Sea (FOB)'!H14 -> 45765
... A47: море | B47: FOB | C47: ='Sea (FOB)'!$F$2 -> 20GP COC | D47: ='Sea (FOB)'!A48 -> DALIAN | E47: ='Sea (FOB)'!B48 -> VLADIVISTOK COMMERCIAL | G47: ='Sea (FOB)'!F48 -> 1725 | P47: ='Sea (FOB)'!H48 -> 45766
A48: море | B48: FOB | C48: ='Sea (FOB)'!$G$2 -> 40HQ COC | D48: ='Sea (FOB)'!A3 -> HONG KONG | E48: ='Sea (FOB)'!B3 -> VLADIVISTOK COMMERCIAL/FISHERY | G48: ='Sea (FOB)'!G3 -> 4500 | P48: ='Sea (FOB)'!H3 -> 45763
A49: море | B49: FOB | C49: ='Sea (FOB)'!$G$2 -> 40HQ COC | D49: ='Sea (FOB)'!A4 -> NANSHA | E49: ='Sea (FOB)'!B4 -> Vrangel Bay (VOSTOCHNY) | G49: ='Sea (FOB)'!G4 -> 2550 | P49: ='Sea (FOB)'!H4 -> 45770
A50: море | B50: FOB | C50: ='Sea (FOB)'!$G$2 -> 40HQ COC | D50: ='Sea (FOB)'!A5 -> NANSHA | E50: ='Sea (FOB)'!B5 -> VLADIVISTOK COMMERCIAL/FISHERY | G50: ='Sea (FOB)'!G5 -> 2750 | P50: ='Sea (FOB)'!H5 -> 45763
A51: море | B51: FOB | C51: ='Sea (FOB)'!$G$2 -> 40HQ COC | D51: ='Sea (FOB)'!A6 -> NANSHA | E51: ='Sea (FOB)'!B6 -> VLADIVISTOK COMMERCIAL | G51: ='Sea (FOB)'!G6 -> 2525 | P51: ='Sea (FOB)'!H6 -> 45765
A52: море | B52: FOB | C52: ='Sea (FOB)'!$G$2 -> 40HQ COC | D52: ='Sea (FOB)'!A7 -> SEHKOU | E52: ='Sea (FOB)'!B7 -> VLADIVISTOK COMMERCIAL/FISHERY | G52: ='Sea (FOB)'!G7 -> 2550 | P52: ='Sea (FOB)'!H7 -> 45764
A53: море | B53: FOB | C53: ='Sea (FOB)'!$G$2 -> 40HQ COC | D53: ='Sea (FOB)'!A8 -> YANTIAN | E53: ='Sea (FOB)'!B8 -> Vrangel Bay (VOSTOCHNY) | G53: ='Sea (FOB)'!G8 -> 2600 | P53: ='Sea (FOB)'!H8 -> 45769
A54: море | B54: FOB | C54: ='Sea (FOB)'!$G$2 -> 40HQ COC | D54: ='Sea (FOB)'!A9 -> YANTIAN | E54: ='Sea (FOB)'!B9 -> VLADIVISTOK COMMERCIAL | G54: ='Sea (FOB)'!G9 -> 2575 | P54: ='Sea (FOB)'!H9 -> 45761
A55: море | B55: FOB | C55: ='Sea (FOB)'!$G$2 -> 40HQ COC | D55: ='Sea (FOB)'!A10 -> XIAMEN | E55: ='Sea (FOB)'!B10 -> Vrangel Bay (VOSTOCHNY) | G55: ='Sea (FOB)'!G10 -> 2800 | P55: ='Sea (FOB)'!H10 -> 45772
A56: море | B56: FOB | C56: ='Sea (FOB)'!$G$2 -> 40HQ COC | D56: ='Sea (FOB)'!A11 -> XIAMEN | E56: ='Sea (FOB)'!B11 -> VLADIVISTOK COMMERCIAL/FISHERY | G56: ='Sea (FOB)'!G11 -> 2700 | P56: ='Sea (FOB)'!H11 -> 45759
A57: море | B57: FOB | C57: ='Sea (FOB)'!$G$2 -> 40HQ COC | D57: ='Sea (FOB)'!A12 -> XIAMEN | E57: ='Sea (FOB)'!B12 -> VLADIVISTOK COMMERCIAL | G57: ='Sea (FOB)'!G12 -> 2700 | P57: ='Sea (FOB)'!H12 -> 45763
A58: море | B58: FOB | C58: ='Sea (FOB)'!$G$2 -> 40HQ COC | D58: ='Sea (FOB)'!A13 -> SHANGHAI | E58: ='Sea (FOB)'!B13 -> VLADIVISTOK COMMERCIAL/FISHERY | G58: ='Sea (FOB)'!G13 -> 2110 | P58: ='Sea (FOB)'!H13 -> 45765
A59: море | B59: FOB | C59: ='Sea (FOB)'!$G$2 -> 40HQ COC | D59: ='Sea (FOB)'!A14 -> SHANGHAI | E59: ='Sea (FOB)'!B14 -> VLADIVISTOK COMMERCIAL/FISHERY | G59: ='Sea (FOB)'!G14 -> 2110 | P59: ='Sea (FOB)'!H14 -> 45765
... A93: море | B93: FOB | C93: ='Sea (FOB)'!$G$2 -> 40HQ COC | D93: ='Sea (FOB)'!A48 -> DALIAN | E93: ='Sea (FOB)'!B48 -> VLADIVISTOK COMMERCIAL | G93: ='Sea (FOB)'!G48 -> 2100 | P93: ='Sea (FOB)'!H48 -> 45766
A94: море | B94: FOB | C94: ='Sea (FOB)'!$G$55 -> FILO 40HQ (USD) COC | D94: ='Sea (FOB)'!A56 -> QINGDAO | E94: ='Sea (FOB)'!B56 -> St.PETERSBURG(PLP) | G94: ='Sea (FOB)'!G56 -> 5255 | H94: - | K94: включена | M94: - | P94: ='Sea (FOB)'!H56 -> 45763
A95: море | B95: FOB | C95: ='Sea (FOB)'!$G$55 -> FILO 40HQ (USD) COC | D95: ='Sea (FOB)'!A57 -> QINGDAO | E95: ='Sea (FOB)'!B57 -> St.PETERSBURG(PLP) | G95: ='Sea (FOB)'!G57 -> 5350 | H95: - | K95: включена | M95: - | P95: ='Sea (FOB)'!H57 -> 45762
A96: море | B96: FOB | C96: ='Sea (FOB)'!$G$55 -> FILO 40HQ (USD) COC | D96: ='Sea (FOB)'!A58 -> QINGDAO | E96: ='Sea (FOB)'!B58 -> St.PETERSBURG(FCT) | G96: ='Sea (FOB)'!G58 -> 5200 | H96: - | K96: включена | M96: - | P96: ='Sea (FOB)'!H58 -> 45773
A97: море | B97: FOB | C97: ='Sea (FOB)'!$G$55 -> FILO 40HQ (USD) COC | D97: ='Sea (FOB)'!A59 -> RIZHAO | E97: ='Sea (FOB)'!B59 -> St.PETERSBURG(FCT) | G97: ='Sea (FOB)'!G59 -> 5410 | H97: - | K97: включена | M97: - | P97: ='Sea (FOB)'!H59 -> 45771
A98: море | B98: FOB | C98: ='Sea (FOB)'!$G$55 -> FILO 40HQ (USD) COC | D98: ='Sea (FOB)'!A60 -> RIZHAO | E98: ='Sea (FOB)'!B60 -> St.PETERSBURG(FCT) | G98: ='Sea (FOB)'!G60 -> 5200 | H98: - | K98: включена | M98: - | P98: ='Sea (FOB)'!H60 -> 45773
A99: море | B99: FOB | C99: ='Sea (FOB)'!$G$55 -> FILO 40HQ (USD) COC | D99: ='Sea (FOB)'!A61 -> SHANGHAI | E99: ='Sea (FOB)'!B61 -> St.PETERSBURG(PLP) | G99: ='Sea (FOB)'!G61 -> 5255 | H99: - | K99: включена | M99: - | P99: ='Sea (FOB)'!H61 -> 45766
A100: море | B100: FOB | C100: ='Sea (FOB)'!$G$55 -> FILO 40HQ (USD) COC | D100: ='Sea (FOB)'!A62 -> SHANGHAI | E100: ='Sea (FOB)'!B62 -> St.PETERSBURG(PLP) | G100: ='Sea (FOB)'!G62 -> 5350 | H100: - | K100: включена | M100: - | P100: ='Sea (FOB)'!H62 -> 45765
A101: море | B101: FOB | C101: ='Sea (FOB)'!$G$55 -> FILO 40HQ (USD) COC | D101: ='Sea (FOB)'!A63 -> SHANGHAI | E101: ='Sea (FOB)'!B63 -> St.PETERSBURG(Bronka) | G101: ='Sea (FOB)'!G63 -> 5410 | H101: - | K101: включена | M101: - | P101: ='Sea (FOB)'!H63 -> 45781
A102: море | B102: FOB | C102: ='Sea (FOB)'!$G$55 -> FILO 40HQ (USD) COC | D102: ='Sea (FOB)'!A64 -> SHANGHAI | E102: ='Sea (FOB)'!B64 -> St.PETERSBURG(FCT) | G102: ='Sea (FOB)'!G64 -> 5300 | H102: - | K102: включена | M102: - | P102: ='Sea (FOB)'!H64 -> 45769
A103: море | B103: FOB | C103: ='Sea (FOB)'!$G$55 -> FILO 40HQ (USD) COC | D103: ='Sea (FOB)'!A65 -> NINGBO | E103: ='Sea (FOB)'!B65 -> St.PETERSBURG(CTSP) | G103: ='Sea (FOB)'!G65 -> 5400 | H103: - | K103: включена | M103: - | P103: ='Sea (FOB)'!H65 -> 45761
A104: море | B104: FOB | C104: ='Sea (FOB)'!$G$55 -> FILO 40HQ (USD) COC | D104: ='Sea (FOB)'!A66 -> NINGBO | E104: ='Sea (FOB)'!B66 -> St.PETERSBURG(FCT) | G104: ='Sea (FOB)'!G66 -> 5450 | H104: - | K104: включена | M104: - | P104: ='Sea (FOB)'!H66 -> 45767
A105: море | B105: FOB | C105: ='Sea (FOB)'!$G$55 -> FILO 40HQ (USD) COC | D105: ='Sea (FOB)'!A67 -> NANSHA | E105: ='Sea (FOB)'!B67 -> St.PETERSBURG(PLP) | G105: ='Sea (FOB)'!G67 -> 5255 | H105: - | K105: включена | M105: - | P105: ='Sea (FOB)'!H67 -> 45769
... A114: море | B114: FOB | C114: ='Sea (FOB)'!$G$55 -> FILO 40HQ (USD) COC | D114: ='Sea (FOB)'!A76 -> TIANJIN | E114: ='Sea (FOB)'!B76 -> St.PETERSBURG(FCT) | G114: ='Sea (FOB)'!G76 -> 5850 | H114: - | K114: включена | M114: - | P114: ='Sea (FOB)'!H76 -> 45764
...
